<?xml version="1.0" ?>
<sdf version="1.7">
  <model name="basic_robot_model">
    <link name="chassis">
      <pose>0 0 0.1 0 0 0</pose>
      <inertial>
        <mass>5.0</mass>
        <inertia>
          <ixx>0.1</ixx>
          <ixy>0.0</ixy>
          <ixz>0.0</ixz>
          <iyy>0.1</iyy>
          <iyz>0.0</iyz>
          <izz>0.1</izz>
        </inertia>
      </inertial>
      <collision name="collision">
        <geometry>
          <box>
            <size>0.5 0.5 0.2</size>
          </box>
        </geometry>
      </collision>
      <visual name="visual">
        <geometry>
          <box>
            <size>0.5 0.5 0.2</size>
          </box>
        </geometry>
        <material>
          <ambient>0.0 0.8 0.0 1</ambient>
          <diffuse>0.0 0.8 0.0 1</diffuse>
        </material>
      </visual>
    </link>

    <link name="left_wheel">
      <pose>-0.15 0.3 0 0 0 0</pose>
      <inertial>
        <mass>0.5</mass>
        <inertia>
          <ixx>0.001</ixx>
          <ixy>0.0</ixy>
          <ixz>0.0</ixz>
          <iyy>0.001</iyy>
          <iyz>0.0</iyz>
          <izz>0.001</izz>
        </inertia>
      </inertial>
      <collision name="collision">
        <geometry>
          <cylinder>
            <radius>0.1</radius>
            <length>0.05</length>
          </cylinder>
        </geometry>
      </collision>
      <visual name="visual">
        <geometry>
          <cylinder>
            <radius>0.1</radius>
            <length>0.05</length>
          </cylinder>
        </geometry>
        <material>
          <ambient>0.3 0.3 0.3 1</ambient>
          <diffuse>0.3 0.3 0.3 1</diffuse>
        </material>
      </visual>
    </link>

    <link name="right_wheel">
      <pose>-0.15 -0.3 0 0 0 0</pose>
      <inertial>
        <mass>0.5</mass>
        <inertia>
          <ixx>0.001</ixx>
          <ixy>0.0</ixy>
          <ixz>0.0</ixz>
          <iyy>0.001</iyy>
          <iyz>0.0</iyz>
          <izz>0.001</izz>
        </inertia>
      </inertial>
      <collision name="collision">
        <geometry>
          <cylinder>
            <radius>0.1</radius>
            <length>0.05</length>
          </cylinder>
        </geometry>
      </collision>
      <visual name="visual">
        <geometry>
          <cylinder>
            <radius>0.1</radius>
            <length>0.05</length>
          </cylinder>
        </geometry>
        <material>
          <ambient>0.3 0.3 0.3 1</ambient>
          <diffuse>0.3 0.3 0.3 1</diffuse>
        </material>
      </visual>
    </link>

    <joint name="left_wheel_joint" type="continuous">
      <parent>chassis</parent>
      <child>left_wheel</child>
      <axis>
        <xyz>0 0 1</xyz>
      </axis>
    </joint>

    <joint name="right_wheel_joint" type="continuous">
      <parent>chassis</parent>
      <child>right_wheel</child>
      <axis>
        <xyz>0 0 1</xyz>
      </axis>
    </joint>

    <!-- Simple differential drive plugin -->
    <plugin name="diff_drive" filename="libgazebo_ros_diff_drive.so">
      <left_joint>left_wheel_joint</left_joint>
      <right_joint>right_wheel_joint</right_joint>
      <wheel_separation>0.6</wheel_separation>
      <wheel_diameter>0.2</wheel_diameter>
      <max_wheel_torque>20</max_wheel_torque>
      <max_wheel_acceleration>1.0</max_wheel_acceleration>
      <command_topic>cmd_vel</command_topic>
      <odometry_topic>odom</odometry_topic>
      <odometry_frame>odom</odometry_frame>
      <robot_base_frame>chassis</robot_base_frame>
      <publish_odom>true</publish_odom>
      <publish_wheel_tf>true</publish_wheel_tf>
      <publish_wheel_joint_state>true</publish_wheel_joint_state>
      <ros>
        <namespace>/basic_robot</namespace>
      </ros>
    </plugin>
  </model>
</sdf>